try {
    let a=0;
    console.log(refer);
} catch (error) {
    console.log(error)
}
finally{
    console.log("finally block is executed")
}